Workbook

Sheet Raw_Data
A1: Client_ID | B1: Client_Industry | C1: Region | D1: Month | E1: Revenue_ZAR | F1: Operating_Cost_ZAR | G1: Transactions | H1: Source_System
A2: 1083 | B2: Manufacturing | C2: Western Cape | D2: 45227 | E2: 4639363 | F2: 1635977 | G2: 416 | H2: SAP
A3: 1018 | B3: Financial Services | C3: Gauteng | D3: 45167 | E3: 4659611 | F3: 2338410 | G3: 102 | H3: SAP
A4: 1036 | B4: Healthcare | C4: gauteng | D4: 45137 | E4: 4131670 | F4: 441839 | G4: 440 | H4: CRM
A5: 1083 | B5: Retail | C5: Eastern Cape | D5: 44957 | E5: 2003974 | F5: 1860224 | G5: 303 | H5: Excel Upload
A6: 1081 | B6: Financial Services | C6: KwaZulu-Natal | D6: 44957 | E6: 2372343 | F6: 476215 | G6: 171 | H6: CRM
A7: 1025 | B7: Financial Services | C7: KwaZulu-Natal | D7: 45197 | E7: 3892400 | F7: 3666639 | G7: 354 | H7: Oracle
A8: 1010 | B8: Manufacturing | C8: gauteng | D8: 45077 | E8: 2949325 | F8: 3714836 | G8: 252 | H8: Excel Upload
A9: 1017 | B9: Retail | C9: gauteng | D9: 45107 | E9: 3746226 | F9: 1845913 | G9: 349 | H9: CRM
A10: 1017 | B10: Financial Services | C10: KwaZulu-Natal | D10: 45167 | E10: 1705270 | F10: 2802690 | G10: 285 | H10: Oracle
A11: 1074 | B11: Technology | C11: Western Cape | D11: 44927 | E11: 3097663 | F11: 3201761 | G11: 432 | H11: Oracle
A12: 1090 | B12: Manufacturing | C12: Eastern Cape | D12: 45257 | E12: 1123919 | F12: 3659977 | G12: 11 | H12: Excel Upload
A13: 1100 | B13: Technology | C13: Western Cape | D13: 45197 | E13: 693858 | F13: 3013231 | G13: 122 | H13: CRM
... A20: 1087 | B20: Technology | C20: gauteng | D20: 45197 | E20: 342549 | F20: 2569056 | G20: 221 | H20: Oracle
A21: 1001 | B21: Financial Services | C21: Eastern Cape | D21: 44957 | E21: 2803387 | G21: 43 | H21: SAP
A22: 1000 | B22: Healthcare | C22: gauteng | D22: 45167 | E22: 473390 | F22: 1692324 | G22: 474 | H22: Oracle
A23: 1071 | B23: Technology | C23: Western Cape | D23: 44987 | E23: 4898368 | F23: 3380191 | G23: 461 | H23: Oracle
A24: 1027 | B24: Manufacturing | C24: gauteng | D24: 45197 | E24: 2898366 | F24: 3450001 | G24: 17 | H24: SAP
A25: 1010 | B25: Manufacturing | C25: Western Cape | D25: 45077 | E25: 4027137 | F25: 2184787 | G25: 406 | H25: SAP
A26: 1054 | B26: Financial Services | C26: GAUTENG | D26: 45167 | E26: 3869788 | F26: 208069 | G26: 206 | H26: Oracle
A27: 1004 | B27: Manufacturing | C27: gauteng | D27: 45137 | E27: 2487481 | F27: 995892 | G27: 240 | H27: Excel Upload
A28: 1064 | B28: Retail | C28: Eastern Cape | D28: 45227 | E28: 2260935 | F28: 3491578 | G28: 357 | H28: Oracle
A29: 1062 | B29: Financial Services | C29: Western Cape | D29: 45047 | E29: 238388 | F29: 108337 | G29: 257 | H29: Oracle
A30: 1009 | B30: Manufacturing | C30: Western Cape | D30: 45077 | E30: 2426489 | F30: 1218472 | G30: 292 | H30: Excel Upload
A31: 1100 | B31: Manufacturing | C31: gauteng | D31: 44957 | E31: 3530338 | F31: 3624978 | G31: 358 | H31: Excel Upload
A32: 1055 | B32: Manufacturing | C32: KwaZulu-Natal | D32: 45077 | E32: 4773967 | F32: 1298004 | G32: 420 | H32: SAP
A33: 1002 | B33: Healthcare | C33: Western Cape | D33: 45077 | E33: 108728 | F33: 3469585 | G33: 234 | H33: CRM
... A40: 1016 | B40: Retail | C40: Eastern Cape | D40: 44987 | E40: 673917 | F40: 2643695 | G40: 403 | H40: Excel Upload
A41: 1038 | B41: Healthcare | C41: KwaZulu-Natal | D41: 44987 | E41: 2367694 | G41: 333 | H41: Oracle
A42: 1055 | B42: Manufacturing | C42: Gauteng | D42: 44957 | E42: 3837075 | F42: 901178 | G42: 192 | H42: CRM
A43: 1091 | B43: Technology | C43: Eastern Cape | D43: 45197 | E43: 4259609 | F43: 3549750 | G43: 189 | H43: CRM
A44: 1078 | B44: Manufacturing | C44: Western Cape | D44: 45017 | E44: 3721080 | F44: 2734770 | G44: 237 | H44: CRM
A45: 1094 | B45: Retail | C45: gauteng | D45: 44957 | E45: 3259910 | F45: 835637 | G45: 10 | H45: Oracle
A46: 1003 | B46: Financial Services | C46: Western Cape | D46: 45167 | E46: 43507540 | F46: 503857 | G46: 40 | H46: CRM
A47: 1012 | B47: Healthcare | C47: gauteng | D47: 45227 | E47: 2143741 | F47: 1528912 | G47: 285 | H47: CRM
A48: 1056 | B48: Manufacturing | C48: Gauteng | D48: 44927 | E48: 3392269 | F48: 2491954 | G48: 197 | H48: Excel Upload
A49: 1096 | B49: Financial Services | C49: KwaZulu-Natal | D49: 44987 | E49: 4548261 | F49: 2604791 | G49: 367 | H49: CRM
A50: 1037 | B50: Retail | C50: Western Cape | D50: 45077 | E50: 787535 | F50: 3992425 | G50: 177 | H50: SAP
A51: 1094 | B51: Technology | C51: GAUTENG | D51: 45167 | E51: 3419441 | F51: 3605049 | G51: 110 | H51: Excel Upload
A52: 1028 | B52: Financial Services | C52: Western Cape | D52: 45137 | E52: 3644041 | F52: 3646295 | G52: 284 | H52: Excel Upload
...

Sheet Working_Copy
A1: Client_ID | B1: Client_Industry | C1: Region | D1: Month | E1: Revenue_ZAR | F1: Operating_Cost_ZAR | G1: Transactions | H1: Source_System | I1: Data_Quality_Issue | J1: Revenue_ZAR_Clean
A2: 1083 | B2: Manufacturing | C2: Western Cape | D2: 45227 | E2: 4639363 | F2: 1635977 | G2: 416 | H2: SAP | I2: =IF( F2="","Missing Cost", IF( OR(E2<Outlier_Calculations!$E$1,E2>Outlier_Calculations!$F$1), "Outlier Capped", "Clean" ) ) -> Clean | J2: =IF( E2 < Outlier_Calculations!$E$1, Outlier_Calculations!$E$1, IF( E2 > Outlier_Calculations!$F$1, Outlier_Calculations!$F$1, E2 ) ) -> 4639363
A3: 1018 | B3: Financial Services | C3: Gauteng | D3: 45167 | E3: 4659611 | F3: 2338410 | G3: 102 | H3: SAP | I3: =IF( F3="","Missing Cost", IF( OR(E3<Outlier_Calculations!$E$1,E3>Outlier_Calculations!$F$1), "Outlier Capped", "Clean" ) ) -> Clean | J3: =IF( E3 < Outlier_Calculations!$E$1, Outlier_Calculations!$E$1, IF( E3 > Outlier_Calculations!$F$1, Outlier_Calculations!$F$1, E3 ) ) -> 4659611
A4: 1036 | B4: Healthcare | C4: gauteng | D4: 45137 | E4: 4131670 | F4: 441839 | G4: 440 | H4: CRM | I4: =IF( F4="","Missing Cost", IF( OR(E4<Outlier_Calculations!$E$1,E4>Outlier_Calculations!$F$1), "Outlier Capped", "Clean" ) ) -> Clean | J4: =IF( E4 < Outlier_Calculations!$E$1, Outlier_Calculations!$E$1, IF( E4 > Outlier_Calculations!$F$1, Outlier_Calculations!$F$1, E4 ) ) -> 4131670
A5: 1083 | B5: Retail | C5: Eastern Cape | D5: 44957 | E5: 2003974 | F5: 1860224 | G5: 303 | H5: Excel Upload | I5: =IF( F5="","Missing Cost", IF( OR(E5<Outlier_Calculations!$E$1,E5>Outlier_Calculations!$F$1), "Outlier Capped", "Clean" ) ) -> Clean | J5: =IF( E5 < Outlier_Calculations!$E$1, Outlier_Calculations!$E$1, IF( E5 > Outlier_Calculations!$F$1, Outlier_Calculations!$F$1, E5 ) ) -> 2003974
A6: 1081 | B6: Financial Services | C6: KwaZulu-Natal | D6: 44957 | E6: 2372343 | F6: 476215 | G6: 171 | H6: CRM | I6: =IF( F6="","Missing Cost", IF( OR(E6<Outlier_Calculations!$E$1,E6>Outlier_Calculations!$F$1), "Outlier Capped", "Clean" ) ) -> Clean | J6: =IF( E6 < Outlier_Calculations!$E$1, Outlier_Calculations!$E$1, IF( E6 > Outlier_Calculations!$F$1, Outlier_Calculations!$F$1, E6 ) ) -> 2372343
A7: 1025 | B7: Financial Services | C7: KwaZulu-Natal | D7: 45197 | E7: 3892400 | F7: 3666639 | G7: 354 | H7: Oracle | I7: =IF( F7="","Missing Cost", IF( OR(E7<Outlier_Calculations!$E$1,E7>Outlier_Calculations!$F$1), "Outlier Capped", "Clean" ) ) -> Clean | J7: =IF( E7 < Outlier_Calculations!$E$1, Outlier_Calculations!$E$1, IF( E7 > Outlier_Calculations!$F$1, Outlier_Calculations!$F$1, E7 ) ) -> 3892400
A8: 1010 | B8: Manufacturing | C8: gauteng | D8: 45077 | E8: 2949325 | F8: 3714836 | G8: 252 | H8: Excel Upload | I8: =IF( F8="","Missing Cost", IF( OR(E8<Outlier_Calculations!$E$1,E8>Outlier_Calculations!$F$1), "Outlier Capped", "Clean" ) ) -> Clean | J8: =IF( E8 < Outlier_Calculations!$E$1, Outlier_Calculations!$E$1, IF( E8 > Outlier_Calculations!$F$1, Outlier_Calculations!$F$1, E8 ) ) -> 2949325
A9: 1017 | B9: Retail | C9: gauteng | D9: 45107 | E9: 3746226 | F9: 1845913 | G9: 349 | H9: CRM | I9: =IF( F9="","Missing Cost", IF( OR(E9<Outlier_Calculations!$E$1,E9>Outlier_Calculations!$F$1), "Outlier Capped", "Clean" ) ) -> Clean | J9: =IF( E9 < Outlier_Calculations!$E$1, Outlier_Calculations!$E$1, IF( E9 > Outlier_Calculations!$F$1, Outlier_Calculations!$F$1, E9 ) ) -> 3746226
A10: 1017 | B10: Financial Services | C10: KwaZulu-Natal | D10: 45167 | E10: 1705270 | F10: 2802690 | G10: 285 | H10: Oracle | I10: =IF( F10="","Missing Cost", IF( OR(E10<Outlier_Calculations!$E$1,E10>Outlier_Calculations!$F$1), "Outlier Capped", "Clean" ) ) -> Clean | J10: =IF( E10 < Outlier_Calculations!$E$1, Outlier_Calculations!$E$1, IF( E10 > Outlier_Calculations!$F$1, Outlier_Calculations!$F$1, E10 ) ) -> 1705270
A11: 1074 | B11: Technology | C11: Western Cape | D11: 44927 | E11: 3097663 | F11: 3201761 | G11: 432 | H11: Oracle | I11: =IF( F11="","Missing Cost", IF( OR(E11<Outlier_Calculations!$E$1,E11>Outlier_Calculations!$F$1), "Outlier Capped", "Clean" ) ) -> Clean | J11: =IF( E11 < Outlier_Calculations!$E$1, Outlier_Calculations!$E$1, IF( E11 > Outlier_Calculations!$F$1, Outlier_Calculations!$F$1, E11 ) ) -> 3097663
A12: 1090 | B12: Manufacturing | C12: Eastern Cape | D12: 45257 | E12: 1123919 | F12: 3659977 | G12: 11 | H12: Excel Upload | I12: =IF( F12="","Missing Cost", IF( OR(E12<Outlier_Calculations!$E$1,E12>Outlier_Calculations!$F$1), "Outlier Capped", "Clean" ) ) -> Clean | J12: =IF( E12 < Outlier_Calculations!$E$1, Outlier_Calculations!$E$1, IF( E12 > Outlier_Calculations!$F$1, Outlier_Calculations!$F$1, E12 ) ) -> 1123919
A13: 1100 | B13: Technology | C13: Western Cape | D13: 45197 | E13: 693858 | F13: 3013231 | G13: 122 | H13: CRM | I13: =IF( F13="","Missing Cost", IF( OR(E13<Outlier_Calculations!$E$1,E13>Outlier_Calculations!$F$1), "Outlier Capped", "Clean" ) ) -> Clean | J13: =IF( E13 < Outlier_Calculations!$E$1, Outlier_Calculations!$E$1, IF( E13 > Outlier_Calculations!$F$1, Outlier_Calculations!$F$1, E13 ) ) -> 693858
... A241: 1055 | B241: Technology | C241: gauteng | D241: 45107 | E241: 3770519 | F241: 2128968 | G241: 281 | H241: SAP | I241: =IF( F241="","Missing Cost", IF( OR(E241<Outlier_Calculations!$E$1,E241>Outlier_Calculations!$F$1), "Outlier Capped", "Clean" ) ) -> Clean | J241: =IF( E241 < Outlier_Calculations!$E$1, Outlier_Calculations!$E$1, IF( E241 > Outlier_Calculations!$F$1, Outlier_Calculations!$F$1, E241 ) ) -> 3770519

Sheet Data_Imputation
A1: Client_Industry | B1: Median_Operating_Cost | D1: Operating_Cost_Cleaned
A2: Financial Services | B2: {=MEDIAN(IF(Working_Copy!B:B="Financial Services", Working_Copy!F:F))} -> 1134328 | D2: =IF(ISBLANK(Working_Copy!F2), VLOOKUP(Working_Copy!B2, Data_Imputation!$A$2:$B$10, 2, FALSE), Working_Copy!F2) -> 1635977 | G2: Median_Calculation
A3: Healthcare | B3: {=MEDIAN(IF(Working_Copy!B:B="Healthcare", Working_Copy!F:F))} -> 1584746.5 | D3: =IF(ISBLANK(Working_Copy!F3), VLOOKUP(Working_Copy!B3, Data_Imputation!$A$2:$B$10, 2, FALSE), Working_Copy!F3) -> 2338410
A4: Manufacturing | B4: {=MEDIAN(IF(Working_Copy!B:B="Manufacturing", Working_Copy!F:F))} -> 1943398.5 | D4: =IF(ISBLANK(Working_Copy!F4), VLOOKUP(Working_Copy!B4, Data_Imputation!$A$2:$B$10, 2, FALSE), Working_Copy!F4) -> 441839
A5: Retail | B5: {=MEDIAN(IF(Working_Copy!B:B="Retail", Working_Copy!F:F))} -> 2455432 | D5: =IF(ISBLANK(Working_Copy!F5), VLOOKUP(Working_Copy!B5, Data_Imputation!$A$2:$B$10, 2, FALSE), Working_Copy!F5) -> 1860224
A6: Technology | B6: {=MEDIAN(IF(Working_Copy!B:B="Technology", Working_Copy!F:F))} -> 2128968 | D6: =IF(ISBLANK(Working_Copy!F6), VLOOKUP(Working_Copy!B6, Data_Imputation!$A$2:$B$10, 2, FALSE), Working_Copy!F6) -> 476215
D7: =IF(ISBLANK(Working_Copy!F7), VLOOKUP(Working_Copy!B7, Data_Imputation!$A$2:$B$10, 2, FALSE), Working_Copy!F7) -> 3666639
D8: =IF(ISBLANK(Working_Copy!F8), VLOOKUP(Working_Copy!B8, Data_Imputation!$A$2:$B$10, 2, FALSE), Working_Copy!F8) -> 3714836
D9: =IF(ISBLANK(Working_Copy!F9), VLOOKUP(Working_Copy!B9, Data_Imputation!$A$2:$B$10, 2, FALSE), Working_Copy!F9) -> 1845913
D10: =IF(ISBLANK(Working_Copy!F10), VLOOKUP(Working_Copy!B10, Data_Imputation!$A$2:$B$10, 2, FALSE), Working_Copy!F10) -> 2802690
D11: =IF(ISBLANK(Working_Copy!F11), VLOOKUP(Working_Copy!B11, Data_Imputation!$A$2:$B$10, 2, FALSE), Working_Copy!F11) -> 3201761
D12: =IF(ISBLANK(Working_Copy!F12), VLOOKUP(Working_Copy!B12, Data_Imputation!$A$2:$B$10, 2, FALSE), Working_Copy!F12) -> 3659977
D13: =IF(ISBLANK(Working_Copy!F13), VLOOKUP(Working_Copy!B13, Data_Imputation!$A$2:$B$10, 2, FALSE), Working_Copy!F13) -> 3013231
D14: =IF(ISBLANK(Working_Copy!F14), VLOOKUP(Working_Copy!B14, Data_Imputation!$A$2:$B$10, 2, FALSE), Working_Copy!F14) -> 3516451
D15: =IF(ISBLANK(Working_Copy!F15), VLOOKUP(Working_Copy!B15, Data_Imputation!$A$2:$B$10, 2, FALSE), Working_Copy!F15) -> 696422
D16: =IF(ISBLANK(Working_Copy!F16), VLOOKUP(Working_Copy!B16, Data_Imputation!$A$2:$B$10, 2, FALSE), Working_Copy!F16) -> 1141091
D17: =IF(ISBLANK(Working_Copy!F17), VLOOKUP(Working_Copy!B17, Data_Imputation!$A$2:$B$10, 2, FALSE), Working_Copy!F17) -> 2430792
D18: =IF(ISBLANK(Working_Copy!F18), VLOOKUP(Working_Copy!B18, Data_Imputation!$A$2:$B$10, 2, FALSE), Working_Copy!F18) -> 2767619
... D256: =IF(ISBLANK(Working_Copy!F256), VLOOKUP(Working_Copy!B256, Data_Imputation!$A$2:$B$10, 2, FALSE), Working_Copy!F256) -> #N/A

Sheet Outlier_Calculations
A1: Operating_Cost_ZAR | B1: =_xlfn.QUARTILE.INC(Working_Copy!F:F,1) -> 948702.5 | C1: =_xlfn.QUARTILE.INC(Working_Copy!F:F,3) -> 2874413.2 | D1: =C1 - B1 -> 1925710.8 | E1: =B1 - 1.5 * D1 -> -1939863.6 | F1: =C1 + 1.5 * D1 -> 5762979.4 | J1: B1 (Q1)
J2: C1 (Q3)
J3: D1 (IQR)
J4: E1 (Lower limit)
J5: F1 (Upper limit)

Sheet Clean_Data
A1: Client_ID | B1: Client_Industry | C1: Region | D1: Month | E1: Revenue_ZAR | F1: Operating_Cost_ZAR | G1: Transactions | H1: Source_System
A2: 1083 | B2: Manufacturing | C2: Western Cape | D2: 45227 | E2: 4639363 | F2: 1635977 | G2: 416 | H2: SAP
A3: 1018 | B3: Financial Services | C3: Gauteng | D3: 45167 | E3: 4659611 | F3: 2338410 | G3: 102 | H3: SAP
A4: 1036 | B4: Healthcare | C4: gauteng | D4: 45137 | E4: 4131670 | F4: 441839 | G4: 440 | H4: CRM
A5: 1083 | B5: Retail | C5: Eastern Cape | D5: 44957 | E5: 2003974 | F5: 1860224 | G5: 303 | H5: Excel Upload
A6: 1081 | B6: Financial Services | C6: KwaZulu-Natal | D6: 44957 | E6: 2372343 | F6: 476215 | G6: 171 | H6: CRM
A7: 1025 | B7: Financial Services | C7: KwaZulu-Natal | D7: 45197 | E7: 3892400 | F7: 3666639 | G7: 354 | H7: Oracle
A8: 1010 | B8: Manufacturing | C8: gauteng | D8: 45077 | E8: 2949325 | F8: 3714836 | G8: 252 | H8: Excel Upload
A9: 1017 | B9: Retail | C9: gauteng | D9: 45107 | E9: 3746226 | F9: 1845913 | G9: 349 | H9: CRM
A10: 1017 | B10: Financial Services | C10: KwaZulu-Natal | D10: 45167 | E10: 1705270 | F10: 2802690 | G10: 285 | H10: Oracle
A11: 1074 | B11: Technology | C11: Western Cape | D11: 44927 | E11: 3097663 | F11: 3201761 | G11: 432 | H11: Oracle
A12: 1090 | B12: Manufacturing | C12: Eastern Cape | D12: 45257 | E12: 1123919 | F12: 3659977 | G12: 11 | H12: Excel Upload
A13: 1100 | B13: Technology | C13: Western Cape | D13: 45197 | E13: 693858 | F13: 3013231 | G13: 122 | H13: CRM
... A241: 1055 | B241: Technology | C241: gauteng | D241: 45107 | E241: 3770519 | F241: 2128968 | G241: 281 | H241: SAP

Sheet Data_Cleaning_Summary
A1: Metric | B1: Count | C1: % of Total
A2: Total Rows | B2: =COUNTA(Raw_Data!A:A)-1 -> 255
A3: Clean Records | B3: =B2-B4-B5-B6 -> 217 | C3: =B3/$B$2*100 -> 85.098039
A4: Missing Operating Cost | B4: 12 | C4: =B4/$B$2*100 -> 4.7058824 | H4: Missing Operating Cost (formular) | I4: =COUNTIF(Working_Copy!I:I,"Missing Cost") -> 0
A5: Revenue Outliers | B5: 11 | C5: =B5/$B$2*100 -> 4.3137255 | H5: Revenue Outliers (formular) | I5: =COUNTIF(Working_Copy!I:I,"Outlier") -> 0
A6: Duplicate Records | B6: 15 | C6: =B6/$B$2*100 -> 5.8823529
A11: Initially, Only 85% of the data was analysis ready
A13: 15 duplicate values found and removed; 240 unique values remain.
